[2022-07-12 17:24:45,117] {taskinstance.py:1032} INFO - Dependencies all met for <TaskInstance: data_ingestion_gcs_project_dag-1.download_dataset_task scheduled__2022-07-11T00:00:00+00:00 [queued]>
[2022-07-12 17:24:45,130] {taskinstance.py:1032} INFO - Dependencies all met for <TaskInstance: data_ingestion_gcs_project_dag-1.download_dataset_task scheduled__2022-07-11T00:00:00+00:00 [queued]>
[2022-07-12 17:24:45,131] {taskinstance.py:1238} INFO - 
--------------------------------------------------------------------------------
[2022-07-12 17:24:45,131] {taskinstance.py:1239} INFO - Starting attempt 1 of 2
[2022-07-12 17:24:45,131] {taskinstance.py:1240} INFO - 
--------------------------------------------------------------------------------
[2022-07-12 17:24:45,145] {taskinstance.py:1259} INFO - Executing <Task(BashOperator): download_dataset_task> on 2022-07-11 00:00:00+00:00
[2022-07-12 17:24:45,152] {standard_task_runner.py:52} INFO - Started process 170 to run task
[2022-07-12 17:24:45,159] {standard_task_runner.py:76} INFO - Running: ['***', 'tasks', 'run', 'data_ingestion_gcs_project_dag-1', 'download_dataset_task', 'scheduled__2022-07-11T00:00:00+00:00', '--job-id', '4', '--raw', '--subdir', 'DAGS_FOLDER/upload_to_gcs.py', '--cfg-path', '/tmp/tmpo7cjpcdu', '--error-file', '/tmp/tmpav24noqr']
[2022-07-12 17:24:45,160] {standard_task_runner.py:77} INFO - Job 4: Subtask download_dataset_task
[2022-07-12 17:24:45,266] {logging_mixin.py:109} INFO - Running <TaskInstance: data_ingestion_gcs_project_dag-1.download_dataset_task scheduled__2022-07-11T00:00:00+00:00 [running]> on host d64fe2f89ccf
[2022-07-12 17:24:45,352] {taskinstance.py:1426} INFO - Exporting the following env vars:
AIRFLOW_CTX_DAG_OWNER=***
AIRFLOW_CTX_DAG_ID=data_ingestion_gcs_project_dag-1
AIRFLOW_CTX_TASK_ID=download_dataset_task
AIRFLOW_CTX_EXECUTION_DATE=2022-07-11T00:00:00+00:00
AIRFLOW_CTX_DAG_RUN_ID=scheduled__2022-07-11T00:00:00+00:00
[2022-07-12 17:24:45,354] {subprocess.py:62} INFO - Tmp dir root location: 
 /tmp
[2022-07-12 17:24:45,355] {subprocess.py:74} INFO - Running command: ['bash', '-c', 'kaggle datasets download -dmashlyn/online-retail-ii-uci']
[2022-07-12 17:24:45,374] {subprocess.py:85} INFO - Output:
[2022-07-12 17:24:45,381] {subprocess.py:89} INFO - bash: kaggle: command not found
[2022-07-12 17:24:45,382] {subprocess.py:93} INFO - Command exited with return code 127
[2022-07-12 17:24:45,403] {taskinstance.py:1700} ERROR - Task failed with exception
Traceback (most recent call last):
  File "/home/airflow/.local/lib/python3.7/site-packages/airflow/models/taskinstance.py", line 1329, in _run_raw_task
    self._execute_task_with_callbacks(context)
  File "/home/airflow/.local/lib/python3.7/site-packages/airflow/models/taskinstance.py", line 1455, in _execute_task_with_callbacks
    result = self._execute_task(context, self.task)
  File "/home/airflow/.local/lib/python3.7/site-packages/airflow/models/taskinstance.py", line 1511, in _execute_task
    result = execute_callable(context=context)
  File "/home/airflow/.local/lib/python3.7/site-packages/airflow/operators/bash.py", line 188, in execute
    f'Bash command failed. The command returned a non-zero exit code {result.exit_code}.'
airflow.exceptions.AirflowException: Bash command failed. The command returned a non-zero exit code 127.
[2022-07-12 17:24:45,414] {taskinstance.py:1277} INFO - Marking task as UP_FOR_RETRY. dag_id=data_ingestion_gcs_project_dag-1, task_id=download_dataset_task, execution_date=20220711T000000, start_date=20220712T172445, end_date=20220712T172445
[2022-07-12 17:24:45,432] {standard_task_runner.py:92} ERROR - Failed to execute job 4 for task download_dataset_task
Traceback (most recent call last):
  File "/home/airflow/.local/lib/python3.7/site-packages/airflow/task/task_runner/standard_task_runner.py", line 85, in _start_by_fork
    args.func(args, dag=self.dag)
  File "/home/airflow/.local/lib/python3.7/site-packages/airflow/cli/cli_parser.py", line 48, in command
    return func(*args, **kwargs)
  File "/home/airflow/.local/lib/python3.7/site-packages/airflow/utils/cli.py", line 92, in wrapper
    return f(*args, **kwargs)
  File "/home/airflow/.local/lib/python3.7/site-packages/airflow/cli/commands/task_command.py", line 298, in task_run
    _run_task_by_selected_method(args, dag, ti)
  File "/home/airflow/.local/lib/python3.7/site-packages/airflow/cli/commands/task_command.py", line 107, in _run_task_by_selected_method
    _run_raw_task(args, ti)
  File "/home/airflow/.local/lib/python3.7/site-packages/airflow/cli/commands/task_command.py", line 184, in _run_raw_task
    error_file=args.error_file,
  File "/home/airflow/.local/lib/python3.7/site-packages/airflow/utils/session.py", line 70, in wrapper
    return func(*args, session=session, **kwargs)
  File "/home/airflow/.local/lib/python3.7/site-packages/airflow/models/taskinstance.py", line 1329, in _run_raw_task
    self._execute_task_with_callbacks(context)
  File "/home/airflow/.local/lib/python3.7/site-packages/airflow/models/taskinstance.py", line 1455, in _execute_task_with_callbacks
    result = self._execute_task(context, self.task)
  File "/home/airflow/.local/lib/python3.7/site-packages/airflow/models/taskinstance.py", line 1511, in _execute_task
    result = execute_callable(context=context)
  File "/home/airflow/.local/lib/python3.7/site-packages/airflow/operators/bash.py", line 188, in execute
    f'Bash command failed. The command returned a non-zero exit code {result.exit_code}.'
airflow.exceptions.AirflowException: Bash command failed. The command returned a non-zero exit code 127.
[2022-07-12 17:24:45,453] {local_task_job.py:154} INFO - Task exited with return code 1
[2022-07-12 17:24:45,541] {local_task_job.py:264} INFO - 0 downstream tasks scheduled from follow-on schedule check
