[2022-07-13 10:21:30,817] {taskinstance.py:1032} INFO - Dependencies all met for <TaskInstance: data_ingestion_gcs_project_dag-12.download_dataset_task scheduled__2022-07-12T00:00:00+00:00 [queued]>
[2022-07-13 10:21:30,832] {taskinstance.py:1032} INFO - Dependencies all met for <TaskInstance: data_ingestion_gcs_project_dag-12.download_dataset_task scheduled__2022-07-12T00:00:00+00:00 [queued]>
[2022-07-13 10:21:30,833] {taskinstance.py:1238} INFO - 
--------------------------------------------------------------------------------
[2022-07-13 10:21:30,833] {taskinstance.py:1239} INFO - Starting attempt 2 of 3
[2022-07-13 10:21:30,833] {taskinstance.py:1240} INFO - 
--------------------------------------------------------------------------------
[2022-07-13 10:21:30,855] {taskinstance.py:1259} INFO - Executing <Task(BashOperator): download_dataset_task> on 2022-07-12 00:00:00+00:00
[2022-07-13 10:21:30,873] {standard_task_runner.py:52} INFO - Started process 2010 to run task
[2022-07-13 10:21:30,929] {standard_task_runner.py:76} INFO - Running: ['***', 'tasks', 'run', 'data_ingestion_gcs_project_dag-12', 'download_dataset_task', 'scheduled__2022-07-12T00:00:00+00:00', '--job-id', '7', '--raw', '--subdir', 'DAGS_FOLDER/upload_to_gcs.py', '--cfg-path', '/tmp/tmpsg1i4q6z', '--error-file', '/tmp/tmp84djw6ox']
[2022-07-13 10:21:30,940] {standard_task_runner.py:77} INFO - Job 7: Subtask download_dataset_task
[2022-07-13 10:21:31,109] {logging_mixin.py:109} INFO - Running <TaskInstance: data_ingestion_gcs_project_dag-12.download_dataset_task scheduled__2022-07-12T00:00:00+00:00 [running]> on host 1baccf4ebc57
[2022-07-13 10:21:31,211] {taskinstance.py:1426} INFO - Exporting the following env vars:
AIRFLOW_CTX_DAG_OWNER=***
AIRFLOW_CTX_DAG_ID=data_ingestion_gcs_project_dag-12
AIRFLOW_CTX_TASK_ID=download_dataset_task
AIRFLOW_CTX_EXECUTION_DATE=2022-07-12T00:00:00+00:00
AIRFLOW_CTX_DAG_RUN_ID=scheduled__2022-07-12T00:00:00+00:00
[2022-07-13 10:21:31,213] {subprocess.py:62} INFO - Tmp dir root location: 
 /tmp
[2022-07-13 10:21:31,215] {subprocess.py:74} INFO - Running command: ['bash', '-c', '#!/usr/bin\npip install kaggle\n\nexport KAGGLE_USERNAME=yusufkamorudeen\nexport KAGGLE_KEY=f9e7d64641f620123ab335c78451fdf4\n\n\n\n\n\nDATASET_ID=mashlyn\nDATASET_NAME=online-retail-ii-uci\nFILE_NAME=$DATASET_NAME.csv\n\n\nkaggle datasets download -d $DATASET_ID/$DATASET_NAME --unzip  -f $FILE_NAME -p "/opt/***/$DATASET_ID/$DATASET_NAME"\n\n\n\n\n\n#mv $data_name uk_housing.zip\n\n\n']
[2022-07-13 10:21:31,237] {subprocess.py:85} INFO - Output:
[2022-07-13 10:21:31,955] {subprocess.py:89} INFO - Defaulting to user installation because normal site-packages is not writeable
[2022-07-13 10:21:32,179] {subprocess.py:89} INFO - Requirement already satisfied: kaggle in /home/***/.local/lib/python3.7/site-packages (1.5.12)
[2022-07-13 10:21:32,188] {subprocess.py:89} INFO - Requirement already satisfied: tqdm in /home/***/.local/lib/python3.7/site-packages (from kaggle) (4.64.0)
[2022-07-13 10:21:32,188] {subprocess.py:89} INFO - Requirement already satisfied: python-slugify in /home/***/.local/lib/python3.7/site-packages (from kaggle) (4.0.1)
[2022-07-13 10:21:32,189] {subprocess.py:89} INFO - Requirement already satisfied: python-dateutil in /home/***/.local/lib/python3.7/site-packages (from kaggle) (2.8.2)
[2022-07-13 10:21:32,189] {subprocess.py:89} INFO - Requirement already satisfied: six>=1.10 in /home/***/.local/lib/python3.7/site-packages (from kaggle) (1.16.0)
[2022-07-13 10:21:32,190] {subprocess.py:89} INFO - Requirement already satisfied: certifi in /home/***/.local/lib/python3.7/site-packages (from kaggle) (2020.12.5)
[2022-07-13 10:21:32,190] {subprocess.py:89} INFO - Requirement already satisfied: requests in /home/***/.local/lib/python3.7/site-packages (from kaggle) (2.26.0)
[2022-07-13 10:21:32,191] {subprocess.py:89} INFO - Requirement already satisfied: urllib3 in /home/***/.local/lib/python3.7/site-packages (from kaggle) (1.26.7)
[2022-07-13 10:21:32,220] {subprocess.py:89} INFO - Requirement already satisfied: text-unidecode>=1.3 in /home/***/.local/lib/python3.7/site-packages (from python-slugify->kaggle) (1.3)
[2022-07-13 10:21:32,244] {subprocess.py:89} INFO - Requirement already satisfied: charset-normalizer~=2.0.0 in /home/***/.local/lib/python3.7/site-packages (from requests->kaggle) (2.0.9)
[2022-07-13 10:21:32,245] {subprocess.py:89} INFO - Requirement already satisfied: idna<4,>=2.5 in /home/***/.local/lib/python3.7/site-packages (from requests->kaggle) (3.3)
[2022-07-13 10:21:37,709] {subprocess.py:89} INFO - WARNING: You are using pip version 21.3.1; however, version 22.1.2 is available.
[2022-07-13 10:21:37,711] {subprocess.py:89} INFO - You should consider upgrading via the '/usr/local/bin/python -m pip install --upgrade pip' command.
[2022-07-13 10:21:38,850] {subprocess.py:89} INFO - 404 - Not Found
[2022-07-13 10:21:39,057] {subprocess.py:93} INFO - Command exited with return code 1
[2022-07-13 10:21:39,080] {taskinstance.py:1700} ERROR - Task failed with exception
Traceback (most recent call last):
  File "/home/airflow/.local/lib/python3.7/site-packages/airflow/models/taskinstance.py", line 1329, in _run_raw_task
    self._execute_task_with_callbacks(context)
  File "/home/airflow/.local/lib/python3.7/site-packages/airflow/models/taskinstance.py", line 1455, in _execute_task_with_callbacks
    result = self._execute_task(context, self.task)
  File "/home/airflow/.local/lib/python3.7/site-packages/airflow/models/taskinstance.py", line 1511, in _execute_task
    result = execute_callable(context=context)
  File "/home/airflow/.local/lib/python3.7/site-packages/airflow/operators/bash.py", line 188, in execute
    f'Bash command failed. The command returned a non-zero exit code {result.exit_code}.'
airflow.exceptions.AirflowException: Bash command failed. The command returned a non-zero exit code 1.
[2022-07-13 10:21:39,088] {taskinstance.py:1277} INFO - Marking task as UP_FOR_RETRY. dag_id=data_ingestion_gcs_project_dag-12, task_id=download_dataset_task, execution_date=20220712T000000, start_date=20220713T102130, end_date=20220713T102139
[2022-07-13 10:21:39,107] {standard_task_runner.py:92} ERROR - Failed to execute job 7 for task download_dataset_task
Traceback (most recent call last):
  File "/home/airflow/.local/lib/python3.7/site-packages/airflow/task/task_runner/standard_task_runner.py", line 85, in _start_by_fork
    args.func(args, dag=self.dag)
  File "/home/airflow/.local/lib/python3.7/site-packages/airflow/cli/cli_parser.py", line 48, in command
    return func(*args, **kwargs)
  File "/home/airflow/.local/lib/python3.7/site-packages/airflow/utils/cli.py", line 92, in wrapper
    return f(*args, **kwargs)
  File "/home/airflow/.local/lib/python3.7/site-packages/airflow/cli/commands/task_command.py", line 298, in task_run
    _run_task_by_selected_method(args, dag, ti)
  File "/home/airflow/.local/lib/python3.7/site-packages/airflow/cli/commands/task_command.py", line 107, in _run_task_by_selected_method
    _run_raw_task(args, ti)
  File "/home/airflow/.local/lib/python3.7/site-packages/airflow/cli/commands/task_command.py", line 184, in _run_raw_task
    error_file=args.error_file,
  File "/home/airflow/.local/lib/python3.7/site-packages/airflow/utils/session.py", line 70, in wrapper
    return func(*args, session=session, **kwargs)
  File "/home/airflow/.local/lib/python3.7/site-packages/airflow/models/taskinstance.py", line 1329, in _run_raw_task
    self._execute_task_with_callbacks(context)
  File "/home/airflow/.local/lib/python3.7/site-packages/airflow/models/taskinstance.py", line 1455, in _execute_task_with_callbacks
    result = self._execute_task(context, self.task)
  File "/home/airflow/.local/lib/python3.7/site-packages/airflow/models/taskinstance.py", line 1511, in _execute_task
    result = execute_callable(context=context)
  File "/home/airflow/.local/lib/python3.7/site-packages/airflow/operators/bash.py", line 188, in execute
    f'Bash command failed. The command returned a non-zero exit code {result.exit_code}.'
airflow.exceptions.AirflowException: Bash command failed. The command returned a non-zero exit code 1.
[2022-07-13 10:21:39,146] {local_task_job.py:154} INFO - Task exited with return code 1
[2022-07-13 10:21:39,194] {local_task_job.py:264} INFO - 0 downstream tasks scheduled from follow-on schedule check
