[2022-07-12 20:00:36,817] {taskinstance.py:1032} INFO - Dependencies all met for <TaskInstance: data_ingestion_gcs_project_dag-12.download_dataset_task scheduled__2022-07-11T00:00:00+00:00 [queued]>
[2022-07-12 20:00:36,828] {taskinstance.py:1032} INFO - Dependencies all met for <TaskInstance: data_ingestion_gcs_project_dag-12.download_dataset_task scheduled__2022-07-11T00:00:00+00:00 [queued]>
[2022-07-12 20:00:36,828] {taskinstance.py:1238} INFO - 
--------------------------------------------------------------------------------
[2022-07-12 20:00:36,829] {taskinstance.py:1239} INFO - Starting attempt 21 of 22
[2022-07-12 20:00:36,829] {taskinstance.py:1240} INFO - 
--------------------------------------------------------------------------------
[2022-07-12 20:00:36,843] {taskinstance.py:1259} INFO - Executing <Task(BashOperator): download_dataset_task> on 2022-07-11 00:00:00+00:00
[2022-07-12 20:00:36,849] {standard_task_runner.py:52} INFO - Started process 195 to run task
[2022-07-12 20:00:36,857] {standard_task_runner.py:76} INFO - Running: ['***', 'tasks', 'run', 'data_ingestion_gcs_project_dag-12', 'download_dataset_task', 'scheduled__2022-07-11T00:00:00+00:00', '--job-id', '36', '--raw', '--subdir', 'DAGS_FOLDER/upload_to_gcs.py', '--cfg-path', '/tmp/tmpw6gfnwtn', '--error-file', '/tmp/tmp53enlra9']
[2022-07-12 20:00:36,859] {standard_task_runner.py:77} INFO - Job 36: Subtask download_dataset_task
[2022-07-12 20:00:36,992] {logging_mixin.py:109} INFO - Running <TaskInstance: data_ingestion_gcs_project_dag-12.download_dataset_task scheduled__2022-07-11T00:00:00+00:00 [running]> on host b7c97f870ea6
[2022-07-12 20:00:37,177] {taskinstance.py:1426} INFO - Exporting the following env vars:
AIRFLOW_CTX_DAG_OWNER=***
AIRFLOW_CTX_DAG_ID=data_ingestion_gcs_project_dag-12
AIRFLOW_CTX_TASK_ID=download_dataset_task
AIRFLOW_CTX_EXECUTION_DATE=2022-07-11T00:00:00+00:00
AIRFLOW_CTX_DAG_RUN_ID=scheduled__2022-07-11T00:00:00+00:00
[2022-07-12 20:00:37,179] {subprocess.py:62} INFO - Tmp dir root location: 
 /tmp
[2022-07-12 20:00:37,184] {subprocess.py:74} INFO - Running command: ['bash', '-c', 'kaggle datasets download -d mashlyn/online-retail-ii-uci']
[2022-07-12 20:00:37,200] {subprocess.py:85} INFO - Output:
[2022-07-12 20:00:37,694] {subprocess.py:89} INFO - Traceback (most recent call last):
[2022-07-12 20:00:37,694] {subprocess.py:89} INFO -   File "/home/***/.local/bin/kaggle", line 5, in <module>
[2022-07-12 20:00:37,694] {subprocess.py:89} INFO -     from kaggle.cli import main
[2022-07-12 20:00:37,694] {subprocess.py:89} INFO -   File "/home/***/.local/lib/python3.7/site-packages/kaggle/__init__.py", line 23, in <module>
[2022-07-12 20:00:37,694] {subprocess.py:89} INFO -     api.authenticate()
[2022-07-12 20:00:37,695] {subprocess.py:89} INFO -   File "/home/***/.local/lib/python3.7/site-packages/kaggle/api/kaggle_api_extended.py", line 166, in authenticate
[2022-07-12 20:00:37,695] {subprocess.py:89} INFO -     self.config_file, self.config_dir))
[2022-07-12 20:00:37,695] {subprocess.py:89} INFO - OSError: Could not find kaggle.json. Make sure it's located in /home/***/.kaggle. Or use the environment method.
[2022-07-12 20:00:37,823] {subprocess.py:93} INFO - Command exited with return code 1
[2022-07-12 20:00:37,847] {taskinstance.py:1700} ERROR - Task failed with exception
Traceback (most recent call last):
  File "/home/airflow/.local/lib/python3.7/site-packages/airflow/models/taskinstance.py", line 1329, in _run_raw_task
    self._execute_task_with_callbacks(context)
  File "/home/airflow/.local/lib/python3.7/site-packages/airflow/models/taskinstance.py", line 1455, in _execute_task_with_callbacks
    result = self._execute_task(context, self.task)
  File "/home/airflow/.local/lib/python3.7/site-packages/airflow/models/taskinstance.py", line 1511, in _execute_task
    result = execute_callable(context=context)
  File "/home/airflow/.local/lib/python3.7/site-packages/airflow/operators/bash.py", line 188, in execute
    f'Bash command failed. The command returned a non-zero exit code {result.exit_code}.'
airflow.exceptions.AirflowException: Bash command failed. The command returned a non-zero exit code 1.
[2022-07-12 20:00:37,860] {taskinstance.py:1277} INFO - Marking task as UP_FOR_RETRY. dag_id=data_ingestion_gcs_project_dag-12, task_id=download_dataset_task, execution_date=20220711T000000, start_date=20220712T200036, end_date=20220712T200037
[2022-07-12 20:00:37,887] {standard_task_runner.py:92} ERROR - Failed to execute job 36 for task download_dataset_task
Traceback (most recent call last):
  File "/home/airflow/.local/lib/python3.7/site-packages/airflow/task/task_runner/standard_task_runner.py", line 85, in _start_by_fork
    args.func(args, dag=self.dag)
  File "/home/airflow/.local/lib/python3.7/site-packages/airflow/cli/cli_parser.py", line 48, in command
    return func(*args, **kwargs)
  File "/home/airflow/.local/lib/python3.7/site-packages/airflow/utils/cli.py", line 92, in wrapper
    return f(*args, **kwargs)
  File "/home/airflow/.local/lib/python3.7/site-packages/airflow/cli/commands/task_command.py", line 298, in task_run
    _run_task_by_selected_method(args, dag, ti)
  File "/home/airflow/.local/lib/python3.7/site-packages/airflow/cli/commands/task_command.py", line 107, in _run_task_by_selected_method
    _run_raw_task(args, ti)
  File "/home/airflow/.local/lib/python3.7/site-packages/airflow/cli/commands/task_command.py", line 184, in _run_raw_task
    error_file=args.error_file,
  File "/home/airflow/.local/lib/python3.7/site-packages/airflow/utils/session.py", line 70, in wrapper
    return func(*args, session=session, **kwargs)
  File "/home/airflow/.local/lib/python3.7/site-packages/airflow/models/taskinstance.py", line 1329, in _run_raw_task
    self._execute_task_with_callbacks(context)
  File "/home/airflow/.local/lib/python3.7/site-packages/airflow/models/taskinstance.py", line 1455, in _execute_task_with_callbacks
    result = self._execute_task(context, self.task)
  File "/home/airflow/.local/lib/python3.7/site-packages/airflow/models/taskinstance.py", line 1511, in _execute_task
    result = execute_callable(context=context)
  File "/home/airflow/.local/lib/python3.7/site-packages/airflow/operators/bash.py", line 188, in execute
    f'Bash command failed. The command returned a non-zero exit code {result.exit_code}.'
airflow.exceptions.AirflowException: Bash command failed. The command returned a non-zero exit code 1.
[2022-07-12 20:00:37,916] {local_task_job.py:154} INFO - Task exited with return code 1
[2022-07-12 20:00:38,011] {local_task_job.py:264} INFO - 0 downstream tasks scheduled from follow-on schedule check
